<robot
  name="model">
  <link
    name="base_link">
    <inertial>
      <origin
        xyz="-2.14253394997531E-17 -0.0781059260936229 -0.637872061412663"
        rpy="0 0 0" />
      <mass
        value="1321.36469194655" />
      <inertia
        ixx="0"
        ixy="0"
        ixz="0"
        iyy="0"
        iyz="0"
        izz="0" />
    </inertial>
    <visual>
      <origin
        xyz="0 0 0"
        rpy="0 0 0" />
      <geometry>
        <mesh
          filename="package://model/meshes/base_link.STL" />
      </geometry>
      <material
        name="">
        <color
          rgba="0.698039215686274 0.698039215686274 0.698039215686274 1" />
      </material>
    </visual>
    <collision>
      <origin
        xyz="0 0 0"
        rpy="0 0 0" />
      <geometry>
        <mesh
          filename="package://model/meshes/base_link.STL" />
      </geometry>
    </collision>
  </link>
  <link
    name="wheel_rear_left">
    <inertial>
      <origin
        xyz="0.12065 -8.32667268468867E-15 5.6621374255883E-15"
        rpy="0 0 0" />
      <mass
        value="127.707018240359" />
      <inertia
        ixx="0"
        ixy="0"
        ixz="0"
        iyy="0"
        iyz="0"
        izz="0" />
    </inertial>
    <visual>
      <origin
        xyz="0 0 0"
        rpy="0 0 0" />
      <geometry>
        <mesh
          filename="package://model/meshes/wheel_rear_left.STL" />
      </geometry>
      <material
        name="">
        <color
          rgba="0.698039215686274 0.698039215686274 0.698039215686274 1" />
      </material>
    </visual>
    <collision>
      <origin
        xyz="0 0 0"
        rpy="0 0 0" />
      <geometry>
        <mesh
          filename="package://model/meshes/wheel_rear_left.STL" />
      </geometry>
    </collision>
  </link>
  <joint
    name="axle_rear"
    type="continuous">
    <origin
      xyz="-0.448309999999995 -0.743606368790554 -0.86868"
      rpy="1.5707963267949 0 3.14159265358979" />
    <parent
      link="base_link" />
    <child
      link="wheel_rear_left" />
    <axis
      xyz="-1 0 0" />
  </joint>
  <link
    name="wheel_rear_right">
    <inertial>
      <origin
        xyz="0.12065 0 1.11022302462516E-16"
        rpy="0 0 0" />
      <mass
        value="127.707018240359" />
      <inertia
        ixx="0"
        ixy="0"
        ixz="0"
        iyy="0"
        iyz="0"
        izz="0" />
    </inertial>
    <visual>
      <origin
        xyz="0 0 0"
        rpy="0 0 0" />
      <geometry>
        <mesh
          filename="package://model/meshes/wheel_rear_right.STL" />
      </geometry>
      <material
        name="">
        <color
          rgba="0.698039215686274 0.698039215686274 0.698039215686274 1" />
      </material>
    </visual>
    <collision>
      <origin
        xyz="0 0 0"
        rpy="0 0 0" />
      <geometry>
        <mesh
          filename="package://model/meshes/wheel_rear_right.STL" />
      </geometry>
    </collision>
  </link>
  <joint
    name="axle_rear"
    type="continuous">
    <origin
      xyz="0.44831 -0.743606368790555 -0.868680000000001"
      rpy="1.5707963267949 0 0" />
    <parent
      link="base_link" />
    <child
      link="wheel_rear_right" />
    <axis
      xyz="1 0 0" />
  </joint>
  <link
    name="axle_left">
    <inertial>
      <origin
        xyz="-1.08801856413265E-14 -1.77635683940025E-14 -0.0889"
        rpy="0 0 0" />
      <mass
        value="1.47031106526729" />
      <inertia
        ixx="0"
        ixy="0"
        ixz="0"
        iyy="0"
        iyz="0"
        izz="0" />
    </inertial>
    <visual>
      <origin
        xyz="0 0 0"
        rpy="0 0 0" />
      <geometry>
        <mesh
          filename="package://model/meshes/axle_left.STL" />
      </geometry>
      <material
        name="">
        <color
          rgba="0.698039215686274 0.698039215686274 0.698039215686274 1" />
      </material>
    </visual>
    <collision>
      <origin
        xyz="0 0 0"
        rpy="0 0 0" />
      <geometry>
        <mesh
          filename="package://model/meshes/axle_left.STL" />
      </geometry>
    </collision>
  </link>
  <joint
    name="steering"
    type="revolute">
    <origin
      xyz="-0.448310000000012 1.09891073605216 -1.02108"
      rpy="-1.5707963267949 -6.12303176911189E-17 -1.5707963267949" />
    <parent
      link="base_link" />
    <child
      link="axle_left" />
    <axis
      xyz="0 0 1" />
  </joint>
  <link
    name="wheel_front_left">
    <inertial>
      <origin
        xyz="0.0762000000000001 0.0100000000001637 -1.77635683940025E-14"
        rpy="0 0 0" />
      <mass
        value="31.5066656842991" />
      <inertia
        ixx="0"
        ixy="0"
        ixz="0"
        iyy="0"
        iyz="0"
        izz="0" />
    </inertial>
    <visual>
      <origin
        xyz="0 0 0"
        rpy="0 0 0" />
      <geometry>
        <mesh
          filename="package://model/meshes/wheel_front_left.STL" />
      </geometry>
      <material
        name="">
        <color
          rgba="0.698039215686274 0.698039215686274 0.698039215686274 1" />
      </material>
    </visual>
    <collision>
      <origin
        xyz="0 0 0"
        rpy="0 0 0" />
      <geometry>
        <mesh
          filename="package://model/meshes/wheel_front_left.STL" />
      </geometry>
    </collision>
  </link>
  <joint
    name="axis_left"
    type="continuous">
    <origin
      xyz="0 0.01 0"
      rpy="3.14159265358979 1.5707963267949 0" />
    <parent
      link="axle_left" />
    <child
      link="wheel_front_left" />
    <axis
      xyz="-1 0 0" />
  </joint>
  <link
    name="axle_right">
    <inertial>
      <origin
        xyz="6.88338275267597E-15 5.55111512312578E-15 0.0888999999999999"
        rpy="0 0 0" />
      <mass
        value="1.47031106526729" />
      <inertia
        ixx="0"
        ixy="0"
        ixz="0"
        iyy="0"
        iyz="0"
        izz="0" />
    </inertial>
    <visual>
      <origin
        xyz="0 0 0"
        rpy="0 0 0" />
      <geometry>
        <mesh
          filename="package://model/meshes/axle_right.STL" />
      </geometry>
      <material
        name="">
        <color
          rgba="0.698039215686274 0.698039215686274 0.698039215686274 1" />
      </material>
    </visual>
    <collision>
      <origin
        xyz="0 0 0"
        rpy="0 0 0" />
      <geometry>
        <mesh
          filename="package://model/meshes/axle_right.STL" />
      </geometry>
    </collision>
  </link>
  <joint
    name="steering"
    type="revolute">
    <origin
      xyz="0.448309999999996 1.09891073605216 -1.02108"
      rpy="1.5707963267949 6.12303176911189E-17 1.5707963267949" />
    <parent
      link="base_link" />
    <child
      link="axle_right" />
    <axis
      xyz="0 0 1" />
  </joint>
  <link
    name="wheel_front_right">
    <inertial>
      <origin
        xyz="0.0761999999999962 9.76996261670138E-15 -8.43769498715119E-15"
        rpy="0 0 0" />
      <mass
        value="31.5066656842991" />
      <inertia
        ixx="0"
        ixy="0"
        ixz="0"
        iyy="0"
        iyz="0"
        izz="0" />
    </inertial>
    <visual>
      <origin
        xyz="0 0 0"
        rpy="0 0 0" />
      <geometry>
        <mesh
          filename="package://model/meshes/wheel_front_right.STL" />
      </geometry>
      <material
        name="">
        <color
          rgba="0.698039215686274 0.698039215686274 0.698039215686274 1" />
      </material>
    </visual>
    <collision>
      <origin
        xyz="0 0 0"
        rpy="0 0 0" />
      <geometry>
        <mesh
          filename="package://model/meshes/wheel_front_right.STL" />
      </geometry>
    </collision>
  </link>
  <joint
    name="axle_front"
    type="continuous">
    <origin
      xyz="0 0 0"
      rpy="1.96259273898454 -1.5707963267949 0" />
    <parent
      link="axle_right" />
    <child
      link="wheel_front_right" />
    <axis
      xyz="1 0 0" />
  </joint>
</robot>